Workbook

Sheet WBS
A1: WBS Aplikasi Helpdesk
A2: Prioritas: Must = wajib untuk spesifikasi minimal; Should = melengkapi dan menambah nilai. Semua fitur pada daftar ini dikerjakan.
A3: Estimasi jam (teks biru) adalah perkiraan pribadi dan dapat diubah; subtotal dan total dihitung otomatis.
A5: Kode | B5: Modul / Fitur | C5: Deskripsi | D5: Prioritas | E5: Status | F5: Estimasi (jam)
A6: 1 | B6: Autentikasi & Manajemen User | F6: =SUM(F7:F10) -> 10
A7: 1.1 | B7: Login/logout agen dan admin | C7: Login dengan email dan password, JWT access token + refresh token, logout mencabut sesi. | D7: Must | E7: Diimplementasikan | F7: 3
A8: 1.2 | B8: Role-based access (agent, admin) | C8: Pembatasan akses per role di middleware backend dan menu di tampilan. | D8: Must | E8: Diimplementasikan | F8: 2
A9: 1.3 | B9: Kelola akun agen | C9: Admin menambah, mengubah, dan menonaktifkan akun agen. | D9: Should | E9: Diimplementasikan | F9: 3
A10: 1.4 | B10: Identitas customer anonim (visitor token) | C10: Customer dikenali lewat token anonim di browser tanpa login. | D10: Must | E10: Diimplementasikan | F10: 2
A11: 2 | B11: Manajemen Tiket | F11: =SUM(F12:F20) -> 19
A12: 2.1 | B12: Pembuatan tiket otomatis dari pesan pertama | C12: Pesan pertama customer membuat customer (jika baru) dan tiket berstatus open. | D12: Must | E12: Diimplementasikan | F12: 2
A13: 2.2 | B13: Status tiket | C13: Status open, in_progress, resolved, closed beserta aturan perpindahannya. | D13: Must | E13: Diimplementasikan | F13: 2
A14: 2.3 | B14: Claim dan release tiket | C14: Agen mengambil atau melepas tiket; first-claim-wins saat bersamaan. | D14: Must | E14: Diimplementasikan | F14: 3
A15: 2.4 | B15: Assign ulang oleh admin | C15: Admin memindahkan tiket ke agen lain tanpa mengubah status. | D15: Must | E15: Diimplementasikan | F15: 2
A16: 2.5 | B16: Prioritas tiket | C16: Prioritas low, medium, high yang dapat diubah agen/admin. | D16: Should | E16: Diimplementasikan | F16: 1
A17: 2.6 | B17: Auto-close setelah 24 jam | C17: Tiket resolved otomatis closed setelah 24 jam tanpa balasan customer. | D17: Should | E17: Diimplementasikan | F17: 2
A18: 2.7 | B18: Buka kembali atau buat tiket baru | C18: Chat saat resolved membuka kembali tiket; chat saat closed membuat tiket baru. | D18: Must | E18: Diimplementasikan | F18: 2
A19: 2.8 | B19: Riwayat aktivitas tiket (audit trail) | C19: Pencatatan pembuatan, assign, perubahan status, dan prioritas di ticket_events. | D19: Should | E19: Diimplementasikan | F19: 2
A20: 2.9 | B20: Daftar tiket dengan filter dan pencarian | C20: Daftar tiket dengan filter status dan agen serta pencarian. | D20: Must | E20: Diimplementasikan | F20: 3
A21: 3 | B21: Real-time Chat (Backend) | F21: =SUM(F22:F28) -> 16
A22: 3.1 | B22: Server Socket.IO dengan autentikasi | C22: Handshake memakai JWT (agen/admin) atau visitor token (customer), pembagian room. | D22: Must | E22: Diimplementasikan | F22: 3
A23: 3.2 | B23: Kirim/terima pesan dan penyimpanan | C23: Event message:send dan message:new, pesan disimpan ke PostgreSQL. | D23: Must | E23: Diimplementasikan | F23: 3
A24: 3.3 | B24: Ack pesan dan pencegahan duplikat | C24: message:ack dan client_message_id unik per tiket agar retry tidak menggandakan pesan. | D24: Must | E24: Diimplementasikan | F24: 3
A25: 3.4 | B25: Sinkronisasi saat reconnect | C25: sync:request dengan ID pesan terakhir; server mengirim pesan yang terlewat. | D25: Must | E25: Diimplementasikan | F25: 3
A26: 3.5 | B26: Presence agen online/offline | C26: Status online agen untuk logika pesan otomatis dan notifikasi. | D26: Must | E26: Diimplementasikan | F26: 2
A27: 3.6 | B27: Pesan otomatis sistem saat agen offline | C27: Customer menerima pesan penerimaan ketika tidak ada agen online. | D27: Must | E27: Diimplementasikan | F27: 1
A28: 3.7 | B28: Rate limit pengiriman dari widget | C28: Pembatasan jumlah pesan per visitor untuk mencegah penyalahgunaan. | D28: Should | E28: Diimplementasikan | F28: 1
A29: 4 | B29: Live Chat Widget | F29: =SUM(F30:F35) -> 18
A30: 4.1 | B30: Bubble chat di kanan bawah | C30: Tombol bubble dengan Shadow DOM agar CSS tidak bentrok dengan website induk. | D30: Must | E30: Diimplementasikan | F30: 4
A31: 4.2 | B31: Form identitas singkat | C31: Nama dan email opsional sebelum pesan pertama. | D31: Must | E31: Diimplementasikan | F31: 2
A32: 4.3 | B32: Jendela chat dan riwayat pesan | C32: Tampilan percakapan, input pesan, dan pemuatan riwayat. | D32: Must | E32: Diimplementasikan | F32: 4
A33: 4.4 | B33: Auto-reconnect, antrean offline, indikator koneksi | C33: Pesan pending disimpan lokal dan dikirim ulang saat tersambung; status koneksi ditampilkan. | D33: Must | E33: Diimplementasikan | F33: 5
A34: 4.5 | B34: Pemulihan percakapan saat reload | C34: Percakapan aktif dipulihkan dari visitor token setelah halaman dimuat ulang. | D34: Must | E34: Diimplementasikan | F34: 2
A35: 4.6 | B35: Halaman demo (/demo) | C35: Website contoh yang memasang widget lewat satu tag script. | D35: Must | E35: Diimplementasikan | F35: 1
A36: 5 | B36: Web App Agen/Admin (React) | F36: =SUM(F37:F42) -> 19
A37: 5.1 | B37: Halaman login | C37: Form login dan penyimpanan sesi. | D37: Must | E37: Diimplementasikan | F37: 2
A38: 5.2 | B38: Antrean tiket dan filter | C38: Daftar tiket real-time dengan filter status dan agen. | D38: Must | E38: Diimplementasikan | F38: 4
A39: 5.3 | B39: Layar chat tiket | C39: Percakapan tiket; hanya agen yang ditugaskan dan admin yang dapat membalas. | D39: Must | E39: Diimplementasikan | F39: 5
A40: 5.4 | B40: Aksi tiket | C40: Claim, release, ubah status dan prioritas dari tampilan. | D40: Must | E40: Diimplementasikan | F40: 3
A41: 5.5 | B41: Halaman kelola agen (admin) | C41: Tambah, ubah, dan nonaktifkan agen; hanya tampil untuk admin. | D41: Should | E41: Diimplementasikan | F41: 3
...

Sheet Ringkasan
A1: Ringkasan per Modul
A3: Kode | B3: Modul | C3: Jumlah Fitur | D3: Must | E3: Should | F3: Estimasi (jam)
A4: 1 | B4: Autentikasi & Manajemen User | C4: =COUNTA(WBS!B7:B10) -> 4 | D4: =COUNTIF(WBS!D7:D10,"Must") -> 3 | E4: =COUNTIF(WBS!D7:D10,"Should") -> 1 | F4: =WBS!F6 -> 10
A5: 2 | B5: Manajemen Tiket | C5: =COUNTA(WBS!B12:B20) -> 9 | D5: =COUNTIF(WBS!D12:D20,"Must") -> 6 | E5: =COUNTIF(WBS!D12:D20,"Should") -> 3 | F5: =WBS!F11 -> 19
A6: 3 | B6: Real-time Chat (Backend) | C6: =COUNTA(WBS!B22:B28) -> 7 | D6: =COUNTIF(WBS!D22:D28,"Must") -> 6 | E6: =COUNTIF(WBS!D22:D28,"Should") -> 1 | F6: =WBS!F21 -> 16
A7: 4 | B7: Live Chat Widget | C7: =COUNTA(WBS!B30:B35) -> 6 | D7: =COUNTIF(WBS!D30:D35,"Must") -> 6 | E7: =COUNTIF(WBS!D30:D35,"Should") -> 0 | F7: =WBS!F29 -> 18
A8: 5 | B8: Web App Agen/Admin (React) | C8: =COUNTA(WBS!B37:B42) -> 6 | D8: =COUNTIF(WBS!D37:D42,"Must") -> 4 | E8: =COUNTIF(WBS!D37:D42,"Should") -> 2 | F8: =WBS!F36 -> 19
A9: 6 | B9: Mobile App (Flutter) | C9: =COUNTA(WBS!B44:B49) -> 6 | D9: =COUNTIF(WBS!D44:D49,"Must") -> 6 | E9: =COUNTIF(WBS!D44:D49,"Should") -> 0 | F9: =WBS!F43 -> 21
A10: 7 | B10: Notifikasi | C10: =COUNTA(WBS!B51:B53) -> 3 | D10: =COUNTIF(WBS!D51:D53,"Must") -> 0 | E10: =COUNTIF(WBS!D51:D53,"Should") -> 3 | F10: =WBS!F50 -> 8
A11: 8 | B11: Database & Infrastruktur | C11: =COUNTA(WBS!B55:B58) -> 4 | D11: =COUNTIF(WBS!D55:D58,"Must") -> 4 | E11: =COUNTIF(WBS!D55:D58,"Should") -> 0 | F11: =WBS!F54 -> 11
A12: 9 | B12: Analisis & Dokumentasi | C12: =COUNTA(WBS!B60:B63) -> 4 | D12: =COUNTIF(WBS!D60:D63,"Must") -> 3 | E12: =COUNTIF(WBS!D60:D63,"Should") -> 1 | F12: =WBS!F59 -> 9
B13: TOTAL | C13: =SUM(C4:C12) -> 49 | D13: =SUM(D4:D12) -> 38 | E13: =SUM(E4:E12) -> 11 | F13: =SUM(F4:F12) -> 131
